terminate called after throwing an instance of 'std::out_of_range'
  what():  basic_string::at: __n (which is 0) >= this->size() (which is 0)
==1366461== 144 bytes in 1 blocks are possibly lost in loss record 4 of 4
==1366461==    at 0x483877F: malloc (vg_replace_malloc.c:307)
==1366461==    by 0x49078DF: __cxa_allocate_exception (in /usr/lib/x86_64-linux-gnu/libstdc++.so.6.0.28)
==1366461==    by 0x492FBC9: std::__throw_out_of_range_fmt(char const*, ...) (in /usr/lib/x86_64-linux-gnu/libstdc++.so.6.0.28)
==1366461==    by 0x4996E8E: std::__cxx11::basic_string<char, std::char_traits<char>, std::allocator<char> >::at(unsigned long) (in /usr/lib/x86_64-linux-gnu/libstdc++.so.6.0.28)
==1366461==    by 0x1092EB: main (t2-Andriel.cpp:18)
==1366461== 
